Workbook

Sheet Dashboard
A1: ApplyAbroadLab.com | PhD & Postdoc Application Tracker | P1: Chart data (auto)
A2: Command center for a graduate application campaign | Every card, chart and list below recalculates automatically | Click any card or row to jump to its source
P3: Country | Q3: Count
A4: KEY METRICS | J4: QUICK NAVIGATION | P4: Netherlands | Q4: =COUNTIF('Position Database'!$D$4:$D$200,$P4) -> 6
B5: Target Positions | C5: Emails Sent | D5: Replies Received | E5: Response Rate | F5: Overdue Follow-ups | G5: Upcoming Interviews | H5: Final Acceptances | J5: ▶ Position Database | P5: Sweden | Q5: =COUNTIF('Position Database'!$D$4:$D$200,$P5) -> 3
B6: =COUNTA('Position Database'!$B$4:$B$200) -> 20 | C6: =COUNTA('Communication Tracker'!$E$4:$E$200) -> 20 | D6: =COUNTA('Response Management'!$D$4:$D$119) -> 10 | E6: =IFERROR(COUNTA('Response Management'!$D$4:$D$119)/COUNTA('Communication Tracker'!$E$4:$E$200),0) -> 0.5 | F6: =COUNTIF('Communication Tracker'!$M$4:$M$200,">14") -> 8 | G6: =COUNTIF('Response Management'!$E$4:$E$119,"Interview Invitation") -> 2 | H6: =COUNTIF('Response Management'!$E$4:$E$119,"Accepted") -> 1 | J6: ▶ Communication Tracker | P6: Denmark | Q6: =COUNTIF('Position Database'!$D$4:$D$200,$P6) -> 2
J7: ▶ Response Management | P7: Luxembourg | Q7: =COUNTIF('Position Database'!$D$4:$D$200,$P7) -> 2
B8: POSITIONS BY COUNTRY → Position Database | F8: OUTREACH STATUS → Communication Tracker | J8: ▶ Follow-up Alerts | P8: Switzerland | Q8: =COUNTIF('Position Database'!$D$4:$D$200,$P8) -> 1
J9: ▶ Email Templates | P9: Germany | Q9: =COUNTIF('Position Database'!$D$4:$D$200,$P9) -> 1
J10: ▶ How It Works | P10: Belgium | Q10: =COUNTIF('Position Database'!$D$4:$D$200,$P10) -> 1
P11: Finland | Q11: =COUNTIF('Position Database'!$D$4:$D$200,$P11) -> 1
P12: Norway | Q12: =COUNTIF('Position Database'!$D$4:$D$200,$P12) -> 1
J13: UPCOMING DEADLINES | P13: France | Q13: =COUNTIF('Position Database'!$D$4:$D$200,$P13) -> 1
J14: University | Position | K14: Days | P14: United Kingdom | Q14: =COUNTIF('Position Database'!$D$4:$D$200,$P14) -> 1
J15: =IFERROR(HYPERLINK("#'Position Database'!A"&(MATCH(1,'Position Database'!$Q$4:$Q$200,0)+3),INDEX('Position Database'!$C$4:$C$200,MATCH(1,'Position Database'!$Q$4:$Q$200,0))&" | "&INDEX('Position Database'!$B$4:$B$200,MATCH(1,'Position Database'!$Q$4:$Q$200,0))),"") -> Vrije Universiteit Amsterdam | Post Doc: Learning Interactions in Collective Cell Migration | K15: =IFERROR(INDEX('Position Database'!$J$4:$J$200,MATCH(1,'Position Database'!$Q$4:$Q$200,0)),"") -> 2
J16: =IFERROR(HYPERLINK("#'Position Database'!A"&(MATCH(2,'Position Database'!$Q$4:$Q$200,0)+3),INDEX('Position Database'!$C$4:$C$200,MATCH(2,'Position Database'!$Q$4:$Q$200,0))&" | "&INDEX('Position Database'!$B$4:$B$200,MATCH(2,'Position Database'!$Q$4:$Q$200,0))),"") -> Radboud University | PhD Position: Beyond the Odds - Pathways to Gambling-Related Harm | K16: =IFERROR(INDEX('Position Database'!$J$4:$J$200,MATCH(2,'Position Database'!$Q$4:$Q$200,0)),"") -> 2
J17: =IFERROR(HYPERLINK("#'Position Database'!A"&(MATCH(3,'Position Database'!$Q$4:$Q$200,0)+3),INDEX('Position Database'!$C$4:$C$200,MATCH(3,'Position Database'!$Q$4:$Q$200,0))&" | "&INDEX('Position Database'!$B$4:$B$200,MATCH(3,'Position Database'!$Q$4:$Q$200,0))),"") -> NTNU | PhD Candidate in Children's Media in English (CLEAR Group) | K17: =IFERROR(INDEX('Position Database'!$J$4:$J$200,MATCH(3,'Position Database'!$Q$4:$Q$200,0)),"") -> 2 | P17: Status | Q17: Count
J18: =IFERROR(HYPERLINK("#'Position Database'!A"&(MATCH(4,'Position Database'!$Q$4:$Q$200,0)+3),INDEX('Position Database'!$C$4:$C$200,MATCH(4,'Position Database'!$Q$4:$Q$200,0))&" | "&INDEX('Position Database'!$B$4:$B$200,MATCH(4,'Position Database'!$Q$4:$Q$200,0))),"") -> University of Helsinki | Postdoctoral Fellows in Proteomics: Neurodevelopment and Cancer | K18: =IFERROR(INDEX('Position Database'!$J$4:$J$200,MATCH(4,'Position Database'!$Q$4:$Q$200,0)),"") -> 2 | P18: Sent | Q18: =COUNTIF('Communication Tracker'!$O$4:$O$200,$P18) -> 5
J19: =IFERROR(HYPERLINK("#'Position Database'!A"&(MATCH(5,'Position Database'!$Q$4:$Q$200,0)+3),INDEX('Position Database'!$C$4:$C$200,MATCH(5,'Position Database'!$Q$4:$Q$200,0))&" | "&INDEX('Position Database'!$B$4:$B$200,MATCH(5,'Position Database'!$Q$4:$Q$200,0))),"") -> Uppsala University | Doctoral Student in Environmental Law Specialising in Nuclear Power | K19: =IFERROR(INDEX('Position Database'!$J$4:$J$200,MATCH(5,'Position Database'!$Q$4:$Q$200,0)),"") -> 3 | P19: No Reply | Q19: =COUNTIF('Communication Tracker'!$O$4:$O$200,$P19) -> 5
J20: =IFERROR(HYPERLINK("#'Position Database'!A"&(MATCH(6,'Position Database'!$Q$4:$Q$200,0)+3),INDEX('Position Database'!$C$4:$C$200,MATCH(6,'Position Database'!$Q$4:$Q$200,0))&" | "&INDEX('Position Database'!$B$4:$B$200,MATCH(6,'Position Database'!$Q$4:$Q$200,0))),"") -> Institut Imagine | Two Postdoctoral Positions in Mitochondrial Cell Biology | K20: =IFERROR(INDEX('Position Database'!$J$4:$J$200,MATCH(6,'Position Database'!$Q$4:$Q$200,0)),"") -> 4 | P20: Positive Reply | Q20: =COUNTIF('Communication Tracker'!$O$4:$O$200,$P20) -> 2
J21: =IFERROR(HYPERLINK("#'Position Database'!A"&(MATCH(7,'Position Database'!$Q$4:$Q$200,0)+3),INDEX('Position Database'!$C$4:$C$200,MATCH(7,'Position Database'!$Q$4:$Q$200,0))&" | "&INDEX('Position Database'!$B$4:$B$200,MATCH(7,'Position Database'!$Q$4:$Q$200,0))),"") -> Amsterdam UMC | MSCA-DN PhD in Pharmacological Therapy for Leukodystrophies | K21: =IFERROR(INDEX('Position Database'!$J$4:$J$200,MATCH(7,'Position Database'!$Q$4:$Q$200,0)),"") -> 7 | P21: Neutral Reply | Q21: =COUNTIF('Communication Tracker'!$O$4:$O$200,$P21) -> 3
J22: =IFERROR(HYPERLINK("#'Position Database'!A"&(MATCH(8,'Position Database'!$Q$4:$Q$200,0)+3),INDEX('Position Database'!$C$4:$C$200,MATCH(8,'Position Database'!$Q$4:$Q$200,0))&" | "&INDEX('Position Database'!$B$4:$B$200,MATCH(8,'Position Database'!$Q$4:$Q$200,0))),"") -> Technical University of Denmark | Postdoc: Multiphysics Modelling of Laser-Regolith Interaction (Moon) | K22: =IFERROR(INDEX('Position Database'!$J$4:$J$200,MATCH(8,'Position Database'!$Q$4:$Q$200,0)),"") -> 8 | P22: Rejected | Q22: =COUNTIF('Communication Tracker'!$O$4:$O$200,$P22) -> 2
P23: Interview Invitation | Q23: =COUNTIF('Communication Tracker'!$O$4:$O$200,$P23) -> 2
P24: Accepted | Q24: =COUNTIF('Communication Tracker'!$O$4:$O$200,$P24) -> 1
B27: APPLICATION FUNNEL → Response Management | F27: PHD VS POSTDOC → Position Database | P27: Level | Q27: Count
P28: PhD | Q28: =COUNTIF('Position Database'!$F$4:$F$200,$P28) -> 11
P29: Postdoc | Q29: =COUNTIF('Position Database'!$F$4:$F$200,$P29) -> 9
P32: Stage | Q32: Count
P33: 1. Emails sent | Q33: =COUNTA('Communication Tracker'!$E$4:$E$200) -> 20
P34: 2. Replies received | Q34: =COUNTA('Response Management'!$D$4:$D$119) -> 10
P35: 3. Interview invitations | Q35: =COUNTIF('Response Management'!$E$4:$E$119,"Interview Invitation") -> 2
P36: 4. Final acceptances | Q36: =COUNTIF('Response Management'!$E$4:$E$119,"Accepted") -> 1
A46: NEEDS FOLLOW-UP NOW — top 8 most overdue, pulled live from the Communication Tracker
A47: # | B47: Position Title | C47: University | D47: Country | E47: Days Since | F47: Status | G47: Next Follow-up
A48: 1 | B48: =IFERROR(HYPERLINK("#'Communication Tracker'!A"&(MATCH(1,'Communication Tracker'!$Q$4:$Q$200,0)+3),INDEX('Communication Tracker'!$B$4:$B$200,MATCH(1,'Communication Tracker'!$Q$4:$Q$200,0))),"") -> MSCA-DN PhD in Pharmacological Therapy for Leukodystrophies | C48: =IFERROR(INDEX('Communication Tracker'!$C$4:$C$200,MATCH(1,'Communication Tracker'!$Q$4:$Q$200,0)),"") -> Amsterdam UMC | D48: =IFERROR(INDEX('Communication Tracker'!$D$4:$D$200,MATCH(1,'Communication Tracker'!$Q$4:$Q$200,0)),"") -> Netherlands | E48: =IFERROR(INDEX('Communication Tracker'!$M$4:$M$200,MATCH(1,'Communication Tracker'!$Q$4:$Q$200,0)),"") -> 35 | F48: =IFERROR(INDEX('Communication Tracker'!$O$4:$O$200,MATCH(1,'Communication Tracker'!$Q$4:$Q$200,0)),"") -> No Reply | G48: =IFERROR(INDEX('Communication Tracker'!$N$4:$N$200,MATCH(1,'Communication Tracker'!$Q$4:$Q$200,0)),"") -> 46272
A49: 2 | B49: =IFERROR(HYPERLINK("#'Communication Tracker'!A"&(MATCH(2,'Communication Tracker'!$Q$4:$Q$200,0)+3),INDEX('Communication Tracker'!$B$4:$B$200,MATCH(2,'Communication Tracker'!$Q$4:$Q$200,0))),"") -> PhD Candidate: Multi-Methods Project on Negation Across Languages | C49: =IFERROR(INDEX('Communication Tracker'!$C$4:$C$200,MATCH(2,'Communication Tracker'!$Q$4:$Q$200,0)),"") -> University of Amsterdam | D49: =IFERROR(INDEX('Communication Tracker'!$D$4:$D$200,MATCH(2,'Communication Tracker'!$Q$4:$Q$200,0)),"") -> Netherlands | E49: =IFERROR(INDEX('Communication Tracker'!$M$4:$M$200,MATCH(2,'Communication Tracker'!$Q$4:$Q$200,0)),"") -> 33 | F49: =IFERROR(INDEX('Communication Tracker'!$O$4:$O$200,MATCH(2,'Communication Tracker'!$Q$4:$Q$200,0)),"") -> Neutral Reply | G49: =IFERROR(INDEX('Communication Tracker'!$N$4:$N$200,MATCH(2,'Communication Tracker'!$Q$4:$Q$200,0)),"") -> 46274
A50: 3 | B50: =IFERROR(HYPERLINK("#'Communication Tracker'!A"&(MATCH(3,'Communication Tracker'!$Q$4:$Q$200,0)+3),INDEX('Communication Tracker'!$B$4:$B$200,MATCH(3,'Communication Tracker'!$Q$4:$Q$200,0))),"") -> Postdoctoral Fellows in Proteomics: Neurodevelopment and Cancer | C50: =IFERROR(INDEX('Communication Tracker'!$C$4:$C$200,MATCH(3,'Communication Tracker'!$Q$4:$Q$200,0)),"") -> University of Helsinki | D50: =IFERROR(INDEX('Communication Tracker'!$D$4:$D$200,MATCH(3,'Communication Tracker'!$Q$4:$Q$200,0)),"") -> Finland | E50: =IFERROR(INDEX('Communication Tracker'!$M$4:$M$200,MATCH(3,'Communication Tracker'!$Q$4:$Q$200,0)),"") -> 27 | F50: =IFERROR(INDEX('Communication Tracker'!$O$4:$O$200,MATCH(3,'Communication Tracker'!$Q$4:$Q$200,0)),"") -> Neutral Reply | G50: =IFERROR(INDEX('Communication Tracker'!$N$4:$N$200,MATCH(3,'Communication Tracker'!$Q$4:$Q$200,0)),"") -> 46280
A51: 4 | B51: =IFERROR(HYPERLINK("#'Communication Tracker'!A"&(MATCH(4,'Communication Tracker'!$Q$4:$Q$200,0)+3),INDEX('Communication Tracker'!$B$4:$B$200,MATCH(4,'Communication Tracker'!$Q$4:$Q$200,0))),"") -> PhD: Microfluidics to Observe and Manipulate Coacervate Droplets | C51: =IFERROR(INDEX('Communication Tracker'!$C$4:$C$200,MATCH(4,'Communication Tracker'!$Q$4:$Q$200,0)),"") -> University of Groningen | D51: =IFERROR(INDEX('Communication Tracker'!$D$4:$D$200,MATCH(4,'Communication Tracker'!$Q$4:$Q$200,0)),"") -> Netherlands | E51: =IFERROR(INDEX('Communication Tracker'!$M$4:$M$200,MATCH(4,'Communication Tracker'!$Q$4:$Q$200,0)),"") -> 25 | F51: =IFERROR(INDEX('Communication Tracker'!$O$4:$O$200,MATCH(4,'Communication Tracker'!$Q$4:$Q$200,0)),"") -> No Reply | G51: =IFERROR(INDEX('Communication Tracker'!$N$4:$N$200,MATCH(4,'Communication Tracker'!$Q$4:$Q$200,0)),"") -> 46282
A52: 5 | B52: =IFERROR(HYPERLINK("#'Communication Tracker'!A"&(MATCH(5,'Communication Tracker'!$Q$4:$Q$200,0)+3),INDEX('Communication Tracker'!$B$4:$B$200,MATCH(5,'Communication Tracker'!$Q$4:$Q$200,0))),"") -> Postdoc in Synthesis and Crystal Growth of Molecular Conductors | C52: =IFERROR(INDEX('Communication Tracker'!$C$4:$C$200,MATCH(5,'Communication Tracker'!$Q$4:$Q$200,0)),"") -> Chalmers University of Technology | D52: =IFERROR(INDEX('Communication Tracker'!$D$4:$D$200,MATCH(5,'Communication Tracker'!$Q$4:$Q$200,0)),"") -> Sweden | E52: =IFERROR(INDEX('Communication Tracker'!$M$4:$M$200,MATCH(5,'Communication Tracker'!$Q$4:$Q$200,0)),"") -> 18 | F52: =IFERROR(INDEX('Communication Tracker'!$O$4:$O$200,MATCH(5,'Communication Tracker'!$Q$4:$Q$200,0)),"") -> Interview Invitation | G52: =IFERROR(INDEX('Communication Tracker'!$N$4:$N$200,MATCH(5,'Communication Tracker'!$Q$4:$Q$200,0)),"") -> 46289
A53: 6 | B53: =IFERROR(HYPERLINK("#'Communication Tracker'!A"&(MATCH(6,'Communication Tracker'!$Q$4:$Q$200,0)+3),INDEX('Communication Tracker'!$B$4:$B$200,MATCH(6,'Communication Tracker'!$Q$4:$Q$200,0))),"") -> Research Associate in Steel Structures and Sustainable Design | C53: =IFERROR(INDEX('Communication Tracker'!$C$4:$C$200,MATCH(6,'Communication Tracker'!$Q$4:$Q$200,0)),"") -> University of Sheffield | D53: =IFERROR(INDEX('Communication Tracker'!$D$4:$D$200,MATCH(6,'Communication Tracker'!$Q$4:$Q$200,0)),"") -> United Kingdom | E53: =IFERROR(INDEX('Communication Tracker'!$M$4:$M$200,MATCH(6,'Communication Tracker'!$Q$4:$Q$200,0)),"") -> 16 | F53: =IFERROR(INDEX('Communication Tracker'!$O$4:$O$200,MATCH(6,'Communication Tracker'!$Q$4:$Q$200,0)),"") -> No Reply | G53: =IFERROR(INDEX('Communication Tracker'!$N$4:$N$200,MATCH(6,'Communication Tracker'!$Q$4:$Q$200,0)),"") -> 46291
...

Sheet Position Database
A1: Position Database
A2: One row per target position. Fill in the white cells; grey cells are calculated automatically. | N2: ◀ Back to Dashboard
A3: ID | B3: Position Title | C3: University | D3: Country | E3: City | F3: Level | G3: Research Area | H3: Funding | I3: Deadline | J3: Days to Deadline | K3: Priority | L3: Supervisor | M3: Supervisor Email | N3: Posting Link | O3: Notes | Q3: deadline rank
A4: 1 | B4: Post Doc: Learning Interactions in Collective Cell Migration | C4: Vrije Universiteit Amsterdam | D4: Netherlands | E4: Amsterdam | F4: Postdoc | G4: Physics | H4: Fully Funded | I4: 46295 | J4: =IF(I4="","",I4-TODAY()) -> 2 | K4: High | N4: https://www.academictransfer.com/en/jobs/362788/post-doc-learning-interactions-in-collective-cell-migration/ | Q4: =IF(AND($A4<>"",ISNUMBER(J4),J4>=0),COUNTIFS($J$4:$J$200,">=0",$J$4:$J$200,"<"&J4)+COUNTIF($J$4:J4,J4),"") -> 1
A5: 2 | B5: MSCA-DN PhD in Pharmacological Therapy for Leukodystrophies | C5: Amsterdam UMC | D5: Netherlands | E5: Amsterdam | F5: PhD | G5: Medical Sciences; Neurosciences | H5: Fully Funded | I5: 46300 | J5: =IF(I5="","",I5-TODAY()) -> 7 | K5: Medium | N5: https://www.academictransfer.com/en/jobs/363691/msca-dn-phd-in-pharmacological-therapy-for-leukodystrophies-rome-it/ | Q5: =IF(AND($A5<>"",ISNUMBER(J5),J5>=0),COUNTIFS($J$4:$J$200,">=0",$J$4:$J$200,"<"&J5)+COUNTIF($J$4:J5,J5),"") -> 7
A6: 3 | B6: PhD Positions in Human-Centred Artificial Intelligence | C6: Aalborg University | D6: Denmark | E6: Aalborg | F6: PhD | G6: Human-Centred AI | H6: Fully Funded | I6: 46339 | J6: =IF(I6="","",I6-TODAY()) -> 46 | K6: Low | N6: https://aau.varbi.com/en/what:job/jobID:972965/ | Q6: =IF(AND($A6<>"",ISNUMBER(J6),J6>=0),COUNTIFS($J$4:$J$200,">=0",$J$4:$J$200,"<"&J6)+COUNTIF($J$4:J6,J6),"") -> 15
A7: 4 | B7: PhD Candidate: Multi-Methods Project on Negation Across Languages | C7: University of Amsterdam | D7: Netherlands | E7: Amsterdam | F7: PhD | G7: Language Sciences; Psychology | H7: Fully Funded | I7: 46307 | J7: =IF(I7="","",I7-TODAY()) -> 14 | K7: High | N7: https://www.academictransfer.com/en/jobs/363542/phd-candidate-within-a-multi-methods-project-on-negation-across-languages/ | Q7: =IF(AND($A7<>"",ISNUMBER(J7),J7>=0),COUNTIFS($J$4:$J$200,">=0",$J$4:$J$200,"<"&J7)+COUNTIF($J$4:J7,J7),"") -> 10
A8: 5 | B8: PhD Position: Beyond the Odds - Pathways to Gambling-Related Harm | C8: Radboud University | D8: Netherlands | E8: Nijmegen | F8: PhD | G8: Economics; Psychology | H8: Fully Funded | I8: 46295 | J8: =IF(I8="","",I8-TODAY()) -> 2 | K8: Medium | N8: https://www.academictransfer.com/en/jobs/363826/phd-position-beyond-the-odds-unravelling-pathways-to-gambling-related-harm/ | Q8: =IF(AND($A8<>"",ISNUMBER(J8),J8>=0),COUNTIFS($J$4:$J$200,">=0",$J$4:$J$200,"<"&J8)+COUNTIF($J$4:J8,J8),"") -> 2
A9: 6 | B9: PhD Position in Time-Reflection of Subwavelength THz Waves | C9: ETH Zurich | D9: Switzerland | E9: Zurich | F9: PhD | G9: Physics - Applied Physics | H9: Not Stated | J9: =IF(I9="","",I9-TODAY()) | K9: Low | N9: https://www.jobs.ethz.ch/job/en/JOPG_ethz_VLtNEC6HFLUrmk6007?mw_source=academicpositions | Q9: =IF(AND($A9<>"",ISNUMBER(J9),J9>=0),COUNTIFS($J$4:$J$200,">=0",$J$4:$J$200,"<"&J9)+COUNTIF($J$4:J9,J9),"")
A10: 7 | B10: Postdoc in Machine Learning and Surrogate Modelling | C10: University of Luxembourg | D10: Luxembourg | E10: Esch-sur-Alzette | F10: Postdoc | G10: Computer Science - AI | H10: Fully Funded | J10: =IF(I10="","",I10-TODAY()) | K10: High | N10: https://www.uni.lu/en/jobs/postdoc-in-machine-learning-and-surrogate-modelling/ | Q10: =IF(AND($A10<>"",ISNUMBER(J10),J10>=0),COUNTIFS($J$4:$J$200,">=0",$J$4:$J$200,"<"&J10)+COUNTIF($J$4:J10,J10),"")
A11: 8 | B11: PhD: Microfluidics to Observe and Manipulate Coacervate Droplets | C11: University of Groningen | D11: Netherlands | E11: Groningen | F11: PhD | G11: Engineering; Biological Sciences | H11: Fully Funded | I11: 46306 | J11: =IF(I11="","",I11-TODAY()) -> 13 | K11: Medium | N11: https://www.academictransfer.com/en/jobs/363590/phd-position-using-microfluidics-to-observe-and-manipulate-coacervate-droplets/ | Q11: =IF(AND($A11<>"",ISNUMBER(J11),J11>=0),COUNTIFS($J$4:$J$200,">=0",$J$4:$J$200,"<"&J11)+COUNTIF($J$4:J11,J11),"") -> 9
A12: 9 | B12: Two Postdoctoral Positions in Mitochondrial Cell Biology | C12: Institut Imagine | D12: France | E12: Paris | F12: Postdoc | G12: Biology | H12: Fully Funded | I12: 46297 | J12: =IF(I12="","",I12-TODAY()) -> 4 | K12: Low | N12: https://www.welcometothejungle.com/fr/companies/institut-imagine/jobs/two-2-postdoctoral-positions-in-mitochondrial-cell-biology_paris | Q12: =IF(AND($A12<>"",ISNUMBER(J12),J12>=0),COUNTIFS($J$4:$J$200,">=0",$J$4:$J$200,"<"&J12)+COUNTIF($J$4:J12,J12),"") -> 6
A13: 10 | B13: Doctoral Student in Environmental Law Specialising in Nuclear Power | C13: Uppsala University | D13: Sweden | E13: Uppsala | F13: PhD | G13: Environmental Law | H13: Fully Funded | I13: 46296 | J13: =IF(I13="","",I13-TODAY()) -> 3 | K13: High | N13: https://uu.varbi.com/en/what:job/jobID:953285/ | Q13: =IF(AND($A13<>"",ISNUMBER(J13),J13>=0),COUNTIFS($J$4:$J$200,">=0",$J$4:$J$200,"<"&J13)+COUNTIF($J$4:J13,J13),"") -> 5
A14: 11 | B14: PhD in Integrated Circuit Group on Transceivers for Optical Communications | C14: Eindhoven University of Technology | D14: Netherlands | E14: Eindhoven | F14: PhD | G14: Engineering | H14: Fully Funded | I14: 46313 | J14: =IF(I14="","",I14-TODAY()) -> 20 | K14: Medium | N14: https://www.academictransfer.com/en/jobs/364085/phd-in-the-integrated-circuit-group-on-transceivers-for-optical-communications/ | Q14: =IF(AND($A14<>"",ISNUMBER(J14),J14>=0),COUNTIFS($J$4:$J$200,">=0",$J$4:$J$200,"<"&J14)+COUNTIF($J$4:J14,J14),"") -> 12
A15: 12 | B15: Postdoc in Structural Analysis of Carbon Materials for Energy Storage | C15: Uppsala University | D15: Sweden | E15: Uppsala | F15: Postdoc | G15: Carbon Materials; Electrochemistry | H15: Not Stated | I15: 46321 | J15: =IF(I15="","",I15-TODAY()) -> 28 | K15: Low | N15: https://uu.varbi.com/en/what:job/jobID:972884/ | Q15: =IF(AND($A15<>"",ISNUMBER(J15),J15>=0),COUNTIFS($J$4:$J$200,">=0",$J$4:$J$200,"<"&J15)+COUNTIF($J$4:J15,J15),"") -> 14
A16: 13 | B16: Postdoc: Multiphysics Modelling of Laser-Regolith Interaction (Moon) | C16: Technical University of Denmark | D16: Denmark | E16: Kongens Lyngby | F16: Postdoc | G16: Mechanical Engineering; Space | H16: Not Stated | I16: 46301 | J16: =IF(I16="","",I16-TODAY()) -> 8 | K16: High | N16: https://efzu.fa.em2.oraclecloud.com/hcmUI/CandidateExperience/en/sites/CX_2001/job/8059/ | Q16: =IF(AND($A16<>"",ISNUMBER(J16),J16>=0),COUNTIFS($J$4:$J$200,">=0",$J$4:$J$200,"<"&J16)+COUNTIF($J$4:J16,J16),"") -> 8
A17: 14 | B17: Postdoctoral Researcher in Quantum Communications | C17: University of Luxembourg | D17: Luxembourg | E17: Esch-sur-Alzette | F17: Postdoc | G17: Physics - Quantum Optics | H17: Fully Funded | J17: =IF(I17="","",I17-TODAY()) | K17: Medium | N17: https://www.uni.lu/en/jobs/postdoctoral-researcher-in-quantum-communications/ | Q17: =IF(AND($A17<>"",ISNUMBER(J17),J17>=0),COUNTIFS($J$4:$J$200,">=0",$J$4:$J$200,"<"&J17)+COUNTIF($J$4:J17,J17),"")
A18: 15 | B18: Research Associate in Steel Structures and Sustainable Design | C18: University of Sheffield | D18: United Kingdom | E18: Sheffield | F18: Postdoc | G18: Civil Engineering | H18: Fully Funded | I18: 46317 | J18: =IF(I18="","",I18-TODAY()) -> 24 | K18: Low | N18: https://university-of-sheffield.contactrh.com/jobs/11046/44464617 | Q18: =IF(AND($A18<>"",ISNUMBER(J18),J18>=0),COUNTIFS($J$4:$J$200,">=0",$J$4:$J$200,"<"&J18)+COUNTIF($J$4:J18,J18),"") -> 13
A19: 16 | B19: Postdoc in Synthesis and Crystal Growth of Molecular Conductors | C19: Chalmers University of Technology | D19: Sweden | E19: Gothenburg | F19: Postdoc | G19: Chemistry; Materials Chemistry | H19: Fully Funded | I19: 46310 | J19: =IF(I19="","",I19-TODAY()) -> 17 | K19: High | L19: Daniel Weber | M19: daniel.weber@chalmers.se | N19: https://www.chalmers.se/en/about-chalmers/work-with-us/vacancies/?rmpage=job&rmjob=15046&rmlang=UK | Q19: =IF(AND($A19<>"",ISNUMBER(J19),J19>=0),COUNTIFS($J$4:$J$200,">=0",$J$4:$J$200,"<"&J19)+COUNTIF($J$4:J19,J19),"") -> 11
A20: 17 | B20: PhD Candidate in Children's Media in English (CLEAR Group) | C20: NTNU | D20: Norway | E20: Trondheim | F20: PhD | G20: Children's Media Studies | H20: Not Stated | I20: 46295 | J20: =IF(I20="","",I20-TODAY()) -> 2 | K20: Medium | N20: https://www.jobbnorge.no/en/available-jobs/job/306713/phd-candidate-in-childrens-media-in-english | Q20: =IF(AND($A20<>"",ISNUMBER(J20),J20>=0),COUNTIFS($J$4:$J$200,">=0",$J$4:$J$200,"<"&J20)+COUNTIF($J$4:J20,J20),"") -> 3
A21: 18 | B21: PhD: Chemical Activity of Air Pollutants via Laser Spectroscopy | C21: Forschungszentrum Jülich | D21: Germany | E21: Jülich | F21: PhD | G21: Environmental Chemistry | H21: Not Stated | J21: =IF(I21="","",I21-TODAY()) | K21: Low | N21: https://recruiting.fz-juelich.de/jobposting/feb0efc501ddc3d5ab9b2c01d600e59045c7cff90 | Q21: =IF(AND($A21<>"",ISNUMBER(J21),J21>=0),COUNTIFS($J$4:$J$200,">=0",$J$4:$J$200,"<"&J21)+COUNTIF($J$4:J21,J21),"")
A22: 19 | B22: Doctoral Fellow: Lunar Resource Production (LuMoCX / ERC) | C22: Ghent University | D22: Belgium | E22: Ghent | F22: PhD | G22: Space Resources | H22: Not Stated | I22: 46363 | J22: =IF(I22="","",I22-TODAY()) -> 70 | K22: High | N22: https://www.ugent.be/en/work/scientific/doctoral-fellow-137 | Q22: =IF(AND($A22<>"",ISNUMBER(J22),J22>=0),COUNTIFS($J$4:$J$200,">=0",$J$4:$J$200,"<"&J22)+COUNTIF($J$4:J22,J22),"") -> 16
A23: 20 | B23: Postdoctoral Fellows in Proteomics: Neurodevelopment and Cancer | C23: University of Helsinki | D23: Finland | E23: Helsinki | F23: Postdoc | G23: Proteomics; Biomedical Science | H23: Not Stated | I23: 46295 | J23: =IF(I23="","",I23-TODAY()) -> 2 | K23: Medium | N23: https://jobs.helsinki.fi/job/Helsinki-Postdoctoral-Research-Fellows-in-Proteomics/1370111857/ | Q23: =IF(AND($A23<>"",ISNUMBER(J23),J23>=0),COUNTIFS($J$4:$J$200,">=0",$J$4:$J$200,"<"&J23)+COUNTIF($J$4:J23,J23),"") -> 4
J24: =IF(I24="","",I24-TODAY()) | Q24: =IF(AND($A24<>"",ISNUMBER(J24),J24>=0),COUNTIFS($J$4:$J$200,">=0",$J$4:$J$200,"<"&J24)+COUNTIF($J$4:J24,J24),"")
J25: =IF(I25="","",I25-TODAY()) | Q25: =IF(AND($A25<>"",ISNUMBER(J25),J25>=0),COUNTIFS($J$4:$J$200,">=0",$J$4:$J$200,"<"&J25)+COUNTIF($J$4:J25,J25),"")
J26: =IF(I26="","",I26-TODAY()) | Q26: =IF(AND($A26<>"",ISNUMBER(J26),J26>=0),COUNTIFS($J$4:$J$200,">=0",$J$4:$J$200,"<"&J26)+COUNTIF($J$4:J26,J26),"")
J27: =IF(I27="","",I27-TODAY()) | Q27: =IF(AND($A27<>"",ISNUMBER(J27),J27>=0),COUNTIFS($J$4:$J$200,">=0",$J$4:$J$200,"<"&J27)+COUNTIF($J$4:J27,J27),"")
J28: =IF(I28="","",I28-TODAY()) | Q28: =IF(AND($A28<>"",ISNUMBER(J28),J28>=0),COUNTIFS($J$4:$J$200,">=0",$J$4:$J$200,"<"&J28)+COUNTIF($J$4:J28,J28),"")
J29: =IF(I29="","",I29-TODAY()) | Q29: =IF(AND($A29<>"",ISNUMBER(J29),J29>=0),COUNTIFS($J$4:$J$200,">=0",$J$4:$J$200,"<"&J29)+COUNTIF($J$4:J29,J29),"")
J30: =IF(I30="","",I30-TODAY()) | Q30: =IF(AND($A30<>"",ISNUMBER(J30),J30>=0),COUNTIFS($J$4:$J$200,">=0",$J$4:$J$200,"<"&J30)+COUNTIF($J$4:J30,J30),"")
J31: =IF(I31="","",I31-TODAY()) | Q31: =IF(AND($A31<>"",ISNUMBER(J31),J31>=0),COUNTIFS($J$4:$J$200,">=0",$J$4:$J$200,"<"&J31)+COUNTIF($J$4:J31,J31),"")
J32: =IF(I32="","",I32-TODAY()) | Q32: =IF(AND($A32<>"",ISNUMBER(J32),J32>=0),COUNTIFS($J$4:$J$200,">=0",$J$4:$J$200,"<"&J32)+COUNTIF($J$4:J32,J32),"")
J33: =IF(I33="","",I33-TODAY()) | Q33: =IF(AND($A33<>"",ISNUMBER(J33),J33>=0),COUNTIFS($J$4:$J$200,">=0",$J$4:$J$200,"<"&J33)+COUNTIF($J$4:J33,J33),"")
J34: =IF(I34="","",I34-TODAY()) | Q34: =IF(AND($A34<>"",ISNUMBER(J34),J34>=0),COUNTIFS($J$4:$J$200,">=0",$J$4:$J$200,"<"&J34)+COUNTIF($J$4:J34,J34),"")
J35: =IF(I35="","",I35-TODAY()) | Q35: =IF(AND($A35<>"",ISNUMBER(J35),J35>=0),COUNTIFS($J$4:$J$200,">=0",$J$4:$J$200,"<"&J35)+COUNTIF($J$4:J35,J35),"")
... J200: =IF(I200="","",I200-TODAY()) | Q200: =IF(AND($A200<>"",ISNUMBER(J200),J200>=0),COUNTIFS($J$4:$J$200,">=0",$J$4:$J$200,"<"&J200)+COUNTIF($J$4:J200,J200),"")

Sheet Communication Tracker
A1: Communication Tracker
A2: Pick the position ID from the drop-down; title, university and country fill in automatically. Dates as yyyy-mm-dd. The follow-up clock stops when a case is closed. | N2: ◀ Back to Dashboard
A3: ID | B3: Position Title | C3: University | D3: Country | E3: First Email | F3: Template | G3: CV Version | H3: Proposal Version | I3: Follow-up 1 | J3: Follow-up 2 | K3: Follow-up 3 | L3: Last Contact | M3: Days Since | N3: Next Follow-up | O3: Status | Q3: urgency rank
A4: 1 | B4: =IFERROR(INDEX('Position Database'!B:B,MATCH($A4,'Position Database'!$A:$A,0)),"") -> Post Doc: Learning Interactions in Collective Cell Migration | C4: =IFERROR(INDEX('Position Database'!C:C,MATCH($A4,'Position Database'!$A:$A,0)),"") -> Vrije Universiteit Amsterdam | D4: =IFERROR(INDEX('Position Database'!D:D,MATCH($A4,'Position Database'!$A:$A,0)),"") -> Netherlands | E4: 46239 | F4: Template A | G4: CV_v4 | H4: Prop_v2 | I4: 46253 | J4: 46267 | L4: =IF(COUNT(E4,I4,J4,K4)=0,"",MAX(E4,I4,J4,K4)) -> 46267 | M4: =IF(OR($A4="",NOT(ISNUMBER(L4))),"",IF(OR(O4="Positive Reply",O4="Accepted",O4="Rejected"),"",TODAY()-L4)) | N4: =IF(OR($A4="",NOT(ISNUMBER(L4))),"",IF(OR(O4="Positive Reply",O4="Accepted",O4="Rejected"),"",L4+14)) | O4: Positive Reply | Q4: =IF(AND($A4<>"",ISNUMBER(M4)),COUNTIF($M$4:$M$200,">"&M4)+COUNTIF($M$4:M4,M4),"")
A5: 2 | B5: =IFERROR(INDEX('Position Database'!B:B,MATCH($A5,'Position Database'!$A:$A,0)),"") -> MSCA-DN PhD in Pharmacological Therapy for Leukodystrophies | C5: =IFERROR(INDEX('Position Database'!C:C,MATCH($A5,'Position Database'!$A:$A,0)),"") -> Amsterdam UMC | D5: =IFERROR(INDEX('Position Database'!D:D,MATCH($A5,'Position Database'!$A:$A,0)),"") -> Netherlands | E5: 46244 | F5: Template A | G5: CV_v4 | H5: Prop_v2 | I5: 46258 | L5: =IF(COUNT(E5,I5,J5,K5)=0,"",MAX(E5,I5,J5,K5)) -> 46258 | M5: =IF(OR($A5="",NOT(ISNUMBER(L5))),"",IF(OR(O5="Positive Reply",O5="Accepted",O5="Rejected"),"",TODAY()-L5)) -> 35 | N5: =IF(OR($A5="",NOT(ISNUMBER(L5))),"",IF(OR(O5="Positive Reply",O5="Accepted",O5="Rejected"),"",L5+14)) -> 46272 | O5: No Reply | Q5: =IF(AND($A5<>"",ISNUMBER(M5)),COUNTIF($M$4:$M$200,">"&M5)+COUNTIF($M$4:M5,M5),"") -> 1
A6: 3 | B6: =IFERROR(INDEX('Position Database'!B:B,MATCH($A6,'Position Database'!$A:$A,0)),"") -> PhD Positions in Human-Centred Artificial Intelligence | C6: =IFERROR(INDEX('Position Database'!C:C,MATCH($A6,'Position Database'!$A:$A,0)),"") -> Aalborg University | D6: =IFERROR(INDEX('Position Database'!D:D,MATCH($A6,'Position Database'!$A:$A,0)),"") -> Denmark | E6: 46280 | F6: Template B | G6: CV_v5 | H6: Prop_v3 | L6: =IF(COUNT(E6,I6,J6,K6)=0,"",MAX(E6,I6,J6,K6)) -> 46280 | M6: =IF(OR($A6="",NOT(ISNUMBER(L6))),"",IF(OR(O6="Positive Reply",O6="Accepted",O6="Rejected"),"",TODAY()-L6)) -> 13 | N6: =IF(OR($A6="",NOT(ISNUMBER(L6))),"",IF(OR(O6="Positive Reply",O6="Accepted",O6="Rejected"),"",L6+14)) -> 46294 | O6: Sent | Q6: =IF(AND($A6<>"",ISNUMBER(M6)),COUNTIF($M$4:$M$200,">"&M6)+COUNTIF($M$4:M6,M6),"") -> 9
A7: 4 | B7: =IFERROR(INDEX('Position Database'!B:B,MATCH($A7,'Position Database'!$A:$A,0)),"") -> PhD Candidate: Multi-Methods Project on Negation Across Languages | C7: =IFERROR(INDEX('Position Database'!C:C,MATCH($A7,'Position Database'!$A:$A,0)),"") -> University of Amsterdam | D7: =IFERROR(INDEX('Position Database'!D:D,MATCH($A7,'Position Database'!$A:$A,0)),"") -> Netherlands | E7: 46246 | F7: Template B | G7: CV_v4 | I7: 46260 | L7: =IF(COUNT(E7,I7,J7,K7)=0,"",MAX(E7,I7,J7,K7)) -> 46260 | M7: =IF(OR($A7="",NOT(ISNUMBER(L7))),"",IF(OR(O7="Positive Reply",O7="Accepted",O7="Rejected"),"",TODAY()-L7)) -> 33 | N7: =IF(OR($A7="",NOT(ISNUMBER(L7))),"",IF(OR(O7="Positive Reply",O7="Accepted",O7="Rejected"),"",L7+14)) -> 46274 | O7: Neutral Reply | Q7: =IF(AND($A7<>"",ISNUMBER(M7)),COUNTIF($M$4:$M$200,">"&M7)+COUNTIF($M$4:M7,M7),"") -> 2
A8: 5 | B8: =IFERROR(INDEX('Position Database'!B:B,MATCH($A8,'Position Database'!$A:$A,0)),"") -> PhD Position: Beyond the Odds - Pathways to Gambling-Related Harm | C8: =IFERROR(INDEX('Position Database'!C:C,MATCH($A8,'Position Database'!$A:$A,0)),"") -> Radboud University | D8: =IFERROR(INDEX('Position Database'!D:D,MATCH($A8,'Position Database'!$A:$A,0)),"") -> Netherlands | E8: 46231 | F8: Template A | G8: CV_v3 | H8: Prop_v1 | I8: 46245 | J8: 46259 | K8: 46273 | L8: =IF(COUNT(E8,I8,J8,K8)=0,"",MAX(E8,I8,J8,K8)) -> 46273 | M8: =IF(OR($A8="",NOT(ISNUMBER(L8))),"",IF(OR(O8="Positive Reply",O8="Accepted",O8="Rejected"),"",TODAY()-L8)) | N8: =IF(OR($A8="",NOT(ISNUMBER(L8))),"",IF(OR(O8="Positive Reply",O8="Accepted",O8="Rejected"),"",L8+14)) | O8: Rejected | Q8: =IF(AND($A8<>"",ISNUMBER(M8)),COUNTIF($M$4:$M$200,">"&M8)+COUNTIF($M$4:M8,M8),"")
A9: 6 | B9: =IFERROR(INDEX('Position Database'!B:B,MATCH($A9,'Position Database'!$A:$A,0)),"") -> PhD Position in Time-Reflection of Subwavelength THz Waves | C9: =IFERROR(INDEX('Position Database'!C:C,MATCH($A9,'Position Database'!$A:$A,0)),"") -> ETH Zurich | D9: =IFERROR(INDEX('Position Database'!D:D,MATCH($A9,'Position Database'!$A:$A,0)),"") -> Switzerland | E9: 46266 | F9: Template B | G9: CV_v5 | H9: Prop_v3 | I9: 46280 | L9: =IF(COUNT(E9,I9,J9,K9)=0,"",MAX(E9,I9,J9,K9)) -> 46280 | M9: =IF(OR($A9="",NOT(ISNUMBER(L9))),"",IF(OR(O9="Positive Reply",O9="Accepted",O9="Rejected"),"",TODAY()-L9)) -> 13 | N9: =IF(OR($A9="",NOT(ISNUMBER(L9))),"",IF(OR(O9="Positive Reply",O9="Accepted",O9="Rejected"),"",L9+14)) -> 46294 | O9: Interview Invitation | Q9: =IF(AND($A9<>"",ISNUMBER(M9)),COUNTIF($M$4:$M$200,">"&M9)+COUNTIF($M$4:M9,M9),"") -> 10
A10: 7 | B10: =IFERROR(INDEX('Position Database'!B:B,MATCH($A10,'Position Database'!$A:$A,0)),"") -> Postdoc in Machine Learning and Surrogate Modelling | C10: =IFERROR(INDEX('Position Database'!C:C,MATCH($A10,'Position Database'!$A:$A,0)),"") -> University of Luxembourg | D10: =IFERROR(INDEX('Position Database'!D:D,MATCH($A10,'Position Database'!$A:$A,0)),"") -> Luxembourg | E10: 46283 | F10: Custom | G10: CV_v5 | H10: Prop_v3 | L10: =IF(COUNT(E10,I10,J10,K10)=0,"",MAX(E10,I10,J10,K10)) -> 46283 | M10: =IF(OR($A10="",NOT(ISNUMBER(L10))),"",IF(OR(O10="Positive Reply",O10="Accepted",O10="Rejected"),"",TODAY()-L10)) -> 10 | N10: =IF(OR($A10="",NOT(ISNUMBER(L10))),"",IF(OR(O10="Positive Reply",O10="Accepted",O10="Rejected"),"",L10+14)) -> 46297 | O10: Sent | Q10: =IF(AND($A10<>"",ISNUMBER(M10)),COUNTIF($M$4:$M$200,">"&M10)+COUNTIF($M$4:M10,M10),"") -> 11
A11: 8 | B11: =IFERROR(INDEX('Position Database'!B:B,MATCH($A11,'Position Database'!$A:$A,0)),"") -> PhD: Microfluidics to Observe and Manipulate Coacervate Droplets | C11: =IFERROR(INDEX('Position Database'!C:C,MATCH($A11,'Position Database'!$A:$A,0)),"") -> University of Groningen | D11: =IFERROR(INDEX('Position Database'!D:D,MATCH($A11,'Position Database'!$A:$A,0)),"") -> Netherlands | E11: 46254 | F11: Template A | G11: CV_v4 | H11: Prop_v2 | I11: 46268 | L11: =IF(COUNT(E11,I11,J11,K11)=0,"",MAX(E11,I11,J11,K11)) -> 46268 | M11: =IF(OR($A11="",NOT(ISNUMBER(L11))),"",IF(OR(O11="Positive Reply",O11="Accepted",O11="Rejected"),"",TODAY()-L11)) -> 25 | N11: =IF(OR($A11="",NOT(ISNUMBER(L11))),"",IF(OR(O11="Positive Reply",O11="Accepted",O11="Rejected"),"",L11+14)) -> 46282 | O11: No Reply | Q11: =IF(AND($A11<>"",ISNUMBER(M11)),COUNTIF($M$4:$M$200,">"&M11)+COUNTIF($M$4:M11,M11),"") -> 4
A12: 9 | B12: =IFERROR(INDEX('Position Database'!B:B,MATCH($A12,'Position Database'!$A:$A,0)),"") -> Two Postdoctoral Positions in Mitochondrial Cell Biology | C12: =IFERROR(INDEX('Position Database'!C:C,MATCH($A12,'Position Database'!$A:$A,0)),"") -> Institut Imagine | D12: =IFERROR(INDEX('Position Database'!D:D,MATCH($A12,'Position Database'!$A:$A,0)),"") -> France | E12: 46259 | F12: Template B | G12: CV_v4 | I12: 46273 | L12: =IF(COUNT(E12,I12,J12,K12)=0,"",MAX(E12,I12,J12,K12)) -> 46273 | M12: =IF(OR($A12="",NOT(ISNUMBER(L12))),"",IF(OR(O12="Positive Reply",O12="Accepted",O12="Rejected"),"",TODAY()-L12)) | N12: =IF(OR($A12="",NOT(ISNUMBER(L12))),"",IF(OR(O12="Positive Reply",O12="Accepted",O12="Rejected"),"",L12+14)) | O12: Positive Reply | Q12: =IF(AND($A12<>"",ISNUMBER(M12)),COUNTIF($M$4:$M$200,">"&M12)+COUNTIF($M$4:M12,M12),"")
A13: 10 | B13: =IFERROR(INDEX('Position Database'!B:B,MATCH($A13,'Position Database'!$A:$A,0)),"") -> Doctoral Student in Environmental Law Specialising in Nuclear Power | C13: =IFERROR(INDEX('Position Database'!C:C,MATCH($A13,'Position Database'!$A:$A,0)),"") -> Uppsala University | D13: =IFERROR(INDEX('Position Database'!D:D,MATCH($A13,'Position Database'!$A:$A,0)),"") -> Sweden | E13: 46223 | F13: Template A | G13: CV_v3 | H13: Prop_v1 | I13: 46237 | J13: 46251 | L13: =IF(COUNT(E13,I13,J13,K13)=0,"",MAX(E13,I13,J13,K13)) -> 46251 | M13: =IF(OR($A13="",NOT(ISNUMBER(L13))),"",IF(OR(O13="Positive Reply",O13="Accepted",O13="Rejected"),"",TODAY()-L13)) | N13: =IF(OR($A13="",NOT(ISNUMBER(L13))),"",IF(OR(O13="Positive Reply",O13="Accepted",O13="Rejected"),"",L13+14)) | O13: Accepted | Q13: =IF(AND($A13<>"",ISNUMBER(M13)),COUNTIF($M$4:$M$200,">"&M13)+COUNTIF($M$4:M13,M13),"")
A14: 11 | B14: =IFERROR(INDEX('Position Database'!B:B,MATCH($A14,'Position Database'!$A:$A,0)),"") -> PhD in Integrated Circuit Group on Transceivers for Optical Communications | C14: =IFERROR(INDEX('Position Database'!C:C,MATCH($A14,'Position Database'!$A:$A,0)),"") -> Eindhoven University of Technology | D14: =IFERROR(INDEX('Position Database'!D:D,MATCH($A14,'Position Database'!$A:$A,0)),"") -> Netherlands | E14: 46285 | F14: Template B | G14: CV_v5 | H14: Prop_v3 | L14: =IF(COUNT(E14,I14,J14,K14)=0,"",MAX(E14,I14,J14,K14)) -> 46285 | M14: =IF(OR($A14="",NOT(ISNUMBER(L14))),"",IF(OR(O14="Positive Reply",O14="Accepted",O14="Rejected"),"",TODAY()-L14)) -> 8 | N14: =IF(OR($A14="",NOT(ISNUMBER(L14))),"",IF(OR(O14="Positive Reply",O14="Accepted",O14="Rejected"),"",L14+14)) -> 46299 | O14: Sent | Q14: =IF(AND($A14<>"",ISNUMBER(M14)),COUNTIF($M$4:$M$200,">"&M14)+COUNTIF($M$4:M14,M14),"") -> 13
A15: 12 | B15: =IFERROR(INDEX('Position Database'!B:B,MATCH($A15,'Position Database'!$A:$A,0)),"") -> Postdoc in Structural Analysis of Carbon Materials for Energy Storage | C15: =IFERROR(INDEX('Position Database'!C:C,MATCH($A15,'Position Database'!$A:$A,0)),"") -> Uppsala University | D15: =IFERROR(INDEX('Position Database'!D:D,MATCH($A15,'Position Database'!$A:$A,0)),"") -> Sweden | E15: 46270 | F15: Custom | G15: CV_v5 | I15: 46284 | L15: =IF(COUNT(E15,I15,J15,K15)=0,"",MAX(E15,I15,J15,K15)) -> 46284 | M15: =IF(OR($A15="",NOT(ISNUMBER(L15))),"",IF(OR(O15="Positive Reply",O15="Accepted",O15="Rejected"),"",TODAY()-L15)) -> 9 | N15: =IF(OR($A15="",NOT(ISNUMBER(L15))),"",IF(OR(O15="Positive Reply",O15="Accepted",O15="Rejected"),"",L15+14)) -> 46298 | O15: No Reply | Q15: =IF(AND($A15<>"",ISNUMBER(M15)),COUNTIF($M$4:$M$200,">"&M15)+COUNTIF($M$4:M15,M15),"") -> 12
A16: 13 | B16: =IFERROR(INDEX('Position Database'!B:B,MATCH($A16,'Position Database'!$A:$A,0)),"") -> Postdoc: Multiphysics Modelling of Laser-Regolith Interaction (Moon) | C16: =IFERROR(INDEX('Position Database'!C:C,MATCH($A16,'Position Database'!$A:$A,0)),"") -> Technical University of Denmark | D16: =IFERROR(INDEX('Position Database'!D:D,MATCH($A16,'Position Database'!$A:$A,0)),"") -> Denmark | E16: 46264 | F16: Template B | G16: CV_v4 | H16: Prop_v2 | I16: 46278 | L16: =IF(COUNT(E16,I16,J16,K16)=0,"",MAX(E16,I16,J16,K16)) -> 46278 | M16: =IF(OR($A16="",NOT(ISNUMBER(L16))),"",IF(OR(O16="Positive Reply",O16="Accepted",O16="Rejected"),"",TODAY()-L16)) -> 15 | N16: =IF(OR($A16="",NOT(ISNUMBER(L16))),"",IF(OR(O16="Positive Reply",O16="Accepted",O16="Rejected"),"",L16+14)) -> 46292 | O16: Neutral Reply | Q16: =IF(AND($A16<>"",ISNUMBER(M16)),COUNTIF($M$4:$M$200,">"&M16)+COUNTIF($M$4:M16,M16),"") -> 8
A17: 14 | B17: =IFERROR(INDEX('Position Database'!B:B,MATCH($A17,'Position Database'!$A:$A,0)),"") -> Postdoctoral Researcher in Quantum Communications | C17: =IFERROR(INDEX('Position Database'!C:C,MATCH($A17,'Position Database'!$A:$A,0)),"") -> University of Luxembourg | D17: =IFERROR(INDEX('Position Database'!D:D,MATCH($A17,'Position Database'!$A:$A,0)),"") -> Luxembourg | E17: 46287 | F17: Template A | G17: CV_v5 | H17: Prop_v3 | L17: =IF(COUNT(E17,I17,J17,K17)=0,"",MAX(E17,I17,J17,K17)) -> 46287 | M17: =IF(OR($A17="",NOT(ISNUMBER(L17))),"",IF(OR(O17="Positive Reply",O17="Accepted",O17="Rejected"),"",TODAY()-L17)) -> 6 | N17: =IF(OR($A17="",NOT(ISNUMBER(L17))),"",IF(OR(O17="Positive Reply",O17="Accepted",O17="Rejected"),"",L17+14)) -> 46301 | O17: Sent | Q17: =IF(AND($A17<>"",ISNUMBER(M17)),COUNTIF($M$4:$M$200,">"&M17)+COUNTIF($M$4:M17,M17),"") -> 14
A18: 15 | B18: =IFERROR(INDEX('Position Database'!B:B,MATCH($A18,'Position Database'!$A:$A,0)),"") -> Research Associate in Steel Structures and Sustainable Design | C18: =IFERROR(INDEX('Position Database'!C:C,MATCH($A18,'Position Database'!$A:$A,0)),"") -> University of Sheffield | D18: =IFERROR(INDEX('Position Database'!D:D,MATCH($A18,'Position Database'!$A:$A,0)),"") -> United Kingdom | E18: 46249 | F18: Template C | G18: CV_v4 | I18: 46263 | J18: 46277 | L18: =IF(COUNT(E18,I18,J18,K18)=0,"",MAX(E18,I18,J18,K18)) -> 46277 | M18: =IF(OR($A18="",NOT(ISNUMBER(L18))),"",IF(OR(O18="Positive Reply",O18="Accepted",O18="Rejected"),"",TODAY()-L18)) -> 16 | N18: =IF(OR($A18="",NOT(ISNUMBER(L18))),"",IF(OR(O18="Positive Reply",O18="Accepted",O18="Rejected"),"",L18+14)) -> 46291 | O18: No Reply | Q18: =IF(AND($A18<>"",ISNUMBER(M18)),COUNTIF($M$4:$M$200,">"&M18)+COUNTIF($M$4:M18,M18),"") -> 6
A19: 16 | B19: =IFERROR(INDEX('Position Database'!B:B,MATCH($A19,'Position Database'!$A:$A,0)),"") -> Postdoc in Synthesis and Crystal Growth of Molecular Conductors | C19: =IFERROR(INDEX('Position Database'!C:C,MATCH($A19,'Position Database'!$A:$A,0)),"") -> Chalmers University of Technology | D19: =IFERROR(INDEX('Position Database'!D:D,MATCH($A19,'Position Database'!$A:$A,0)),"") -> Sweden | E19: 46275 | F19: Custom | G19: CV_v5 | H19: Prop_v3 | L19: =IF(COUNT(E19,I19,J19,K19)=0,"",MAX(E19,I19,J19,K19)) -> 46275 | M19: =IF(OR($A19="",NOT(ISNUMBER(L19))),"",IF(OR(O19="Positive Reply",O19="Accepted",O19="Rejected"),"",TODAY()-L19)) -> 18 | N19: =IF(OR($A19="",NOT(ISNUMBER(L19))),"",IF(OR(O19="Positive Reply",O19="Accepted",O19="Rejected"),"",L19+14)) -> 46289 | O19: Interview Invitation | Q19: =IF(AND($A19<>"",ISNUMBER(M19)),COUNTIF($M$4:$M$200,">"&M19)+COUNTIF($M$4:M19,M19),"") -> 5
A20: 17 | B20: =IFERROR(INDEX('Position Database'!B:B,MATCH($A20,'Position Database'!$A:$A,0)),"") -> PhD Candidate in Children's Media in English (CLEAR Group) | C20: =IFERROR(INDEX('Position Database'!C:C,MATCH($A20,'Position Database'!$A:$A,0)),"") -> NTNU | D20: =IFERROR(INDEX('Position Database'!D:D,MATCH($A20,'Position Database'!$A:$A,0)),"") -> Norway | E20: 46242 | F20: Template A | G20: CV_v4 | H20: Prop_v2 | I20: 46256 | L20: =IF(COUNT(E20,I20,J20,K20)=0,"",MAX(E20,I20,J20,K20)) -> 46256 | M20: =IF(OR($A20="",NOT(ISNUMBER(L20))),"",IF(OR(O20="Positive Reply",O20="Accepted",O20="Rejected"),"",TODAY()-L20)) | N20: =IF(OR($A20="",NOT(ISNUMBER(L20))),"",IF(OR(O20="Positive Reply",O20="Accepted",O20="Rejected"),"",L20+14)) | O20: Rejected | Q20: =IF(AND($A20<>"",ISNUMBER(M20)),COUNTIF($M$4:$M$200,">"&M20)+COUNTIF($M$4:M20,M20),"")
A21: 18 | B21: =IFERROR(INDEX('Position Database'!B:B,MATCH($A21,'Position Database'!$A:$A,0)),"") -> PhD: Chemical Activity of Air Pollutants via Laser Spectroscopy | C21: =IFERROR(INDEX('Position Database'!C:C,MATCH($A21,'Position Database'!$A:$A,0)),"") -> Forschungszentrum Jülich | D21: =IFERROR(INDEX('Position Database'!D:D,MATCH($A21,'Position Database'!$A:$A,0)),"") -> Germany | E21: 46289 | F21: Template B | G21: CV_v5 | L21: =IF(COUNT(E21,I21,J21,K21)=0,"",MAX(E21,I21,J21,K21)) -> 46289 | M21: =IF(OR($A21="",NOT(ISNUMBER(L21))),"",IF(OR(O21="Positive Reply",O21="Accepted",O21="Rejected"),"",TODAY()-L21)) -> 4 | N21: =IF(OR($A21="",NOT(ISNUMBER(L21))),"",IF(OR(O21="Positive Reply",O21="Accepted",O21="Rejected"),"",L21+14)) -> 46303 | O21: Sent | Q21: =IF(AND($A21<>"",ISNUMBER(M21)),COUNTIF($M$4:$M$200,">"&M21)+COUNTIF($M$4:M21,M21),"") -> 15
A22: 19 | B22: =IFERROR(INDEX('Position Database'!B:B,MATCH($A22,'Position Database'!$A:$A,0)),"") -> Doctoral Fellow: Lunar Resource Production (LuMoCX / ERC) | C22: =IFERROR(INDEX('Position Database'!C:C,MATCH($A22,'Position Database'!$A:$A,0)),"") -> Ghent University | D22: =IFERROR(INDEX('Position Database'!D:D,MATCH($A22,'Position Database'!$A:$A,0)),"") -> Belgium | E22: 46277 | F22: Template A | G22: CV_v5 | H22: Prop_v3 | L22: =IF(COUNT(E22,I22,J22,K22)=0,"",MAX(E22,I22,J22,K22)) -> 46277 | M22: =IF(OR($A22="",NOT(ISNUMBER(L22))),"",IF(OR(O22="Positive Reply",O22="Accepted",O22="Rejected"),"",TODAY()-L22)) -> 16 | N22: =IF(OR($A22="",NOT(ISNUMBER(L22))),"",IF(OR(O22="Positive Reply",O22="Accepted",O22="Rejected"),"",L22+14)) -> 46291 | O22: No Reply | Q22: =IF(AND($A22<>"",ISNUMBER(M22)),COUNTIF($M$4:$M$200,">"&M22)+COUNTIF($M$4:M22,M22),"") -> 7
A23: 20 | B23: =IFERROR(INDEX('Position Database'!B:B,MATCH($A23,'Position Database'!$A:$A,0)),"") -> Postdoctoral Fellows in Proteomics: Neurodevelopment and Cancer | C23: =IFERROR(INDEX('Position Database'!C:C,MATCH($A23,'Position Database'!$A:$A,0)),"") -> University of Helsinki | D23: =IFERROR(INDEX('Position Database'!D:D,MATCH($A23,'Position Database'!$A:$A,0)),"") -> Finland | E23: 46252 | F23: Template C | G23: CV_v4 | H23: Prop_v2 | I23: 46266 | L23: =IF(COUNT(E23,I23,J23,K23)=0,"",MAX(E23,I23,J23,K23)) -> 46266 | M23: =IF(OR($A23="",NOT(ISNUMBER(L23))),"",IF(OR(O23="Positive Reply",O23="Accepted",O23="Rejected"),"",TODAY()-L23)) -> 27 | N23: =IF(OR($A23="",NOT(ISNUMBER(L23))),"",IF(OR(O23="Positive Reply",O23="Accepted",O23="Rejected"),"",L23+14)) -> 46280 | O23: Neutral Reply | Q23: =IF(AND($A23<>"",ISNUMBER(M23)),COUNTIF($M$4:$M$200,">"&M23)+COUNTIF($M$4:M23,M23),"") -> 3
B24: =IFERROR(INDEX('Position Database'!B:B,MATCH($A24,'Position Database'!$A:$A,0)),"") | C24: =IFERROR(INDEX('Position Database'!C:C,MATCH($A24,'Position Database'!$A:$A,0)),"") | D24: =IFERROR(INDEX('Position Database'!D:D,MATCH($A24,'Position Database'!$A:$A,0)),"") | L24: =IF(COUNT(E24,I24,J24,K24)=0,"",MAX(E24,I24,J24,K24)) | M24: =IF(OR($A24="",NOT(ISNUMBER(L24))),"",IF(OR(O24="Positive Reply",O24="Accepted",O24="Rejected"),"",TODAY()-L24)) | N24: =IF(OR($A24="",NOT(ISNUMBER(L24))),"",IF(OR(O24="Positive Reply",O24="Accepted",O24="Rejected"),"",L24+14)) | Q24: =IF(AND($A24<>"",ISNUMBER(M24)),COUNTIF($M$4:$M$200,">"&M24)+COUNTIF($M$4:M24,M24),"")
B25: =IFERROR(INDEX('Position Database'!B:B,MATCH($A25,'Position Database'!$A:$A,0)),"") | C25: =IFERROR(INDEX('Position Database'!C:C,MATCH($A25,'Position Database'!$A:$A,0)),"") | D25: =IFERROR(INDEX('Position Database'!D:D,MATCH($A25,'Position Database'!$A:$A,0)),"") | L25: =IF(COUNT(E25,I25,J25,K25)=0,"",MAX(E25,I25,J25,K25)) | M25: =IF(OR($A25="",NOT(ISNUMBER(L25))),"",IF(OR(O25="Positive Reply",O25="Accepted",O25="Rejected"),"",TODAY()-L25)) | N25: =IF(OR($A25="",NOT(ISNUMBER(L25))),"",IF(OR(O25="Positive Reply",O25="Accepted",O25="Rejected"),"",L25+14)) | Q25: =IF(AND($A25<>"",ISNUMBER(M25)),COUNTIF($M$4:$M$200,">"&M25)+COUNTIF($M$4:M25,M25),"")
B26: =IFERROR(INDEX('Position Database'!B:B,MATCH($A26,'Position Database'!$A:$A,0)),"") | C26: =IFERROR(INDEX('Position Database'!C:C,MATCH($A26,'Position Database'!$A:$A,0)),"") | D26: =IFERROR(INDEX('Position Database'!D:D,MATCH($A26,'Position Database'!$A:$A,0)),"") | L26: =IF(COUNT(E26,I26,J26,K26)=0,"",MAX(E26,I26,J26,K26)) | M26: =IF(OR($A26="",NOT(ISNUMBER(L26))),"",IF(OR(O26="Positive Reply",O26="Accepted",O26="Rejected"),"",TODAY()-L26)) | N26: =IF(OR($A26="",NOT(ISNUMBER(L26))),"",IF(OR(O26="Positive Reply",O26="Accepted",O26="Rejected"),"",L26+14)) | Q26: =IF(AND($A26<>"",ISNUMBER(M26)),COUNTIF($M$4:$M$200,">"&M26)+COUNTIF($M$4:M26,M26),"")
B27: =IFERROR(INDEX('Position Database'!B:B,MATCH($A27,'Position Database'!$A:$A,0)),"") | C27: =IFERROR(INDEX('Position Database'!C:C,MATCH($A27,'Position Database'!$A:$A,0)),"") | D27: =IFERROR(INDEX('Position Database'!D:D,MATCH($A27,'Position Database'!$A:$A,0)),"") | L27: =IF(COUNT(E27,I27,J27,K27)=0,"",MAX(E27,I27,J27,K27)) | M27: =IF(OR($A27="",NOT(ISNUMBER(L27))),"",IF(OR(O27="Positive Reply",O27="Accepted",O27="Rejected"),"",TODAY()-L27)) | N27: =IF(OR($A27="",NOT(ISNUMBER(L27))),"",IF(OR(O27="Positive Reply",O27="Accepted",O27="Rejected"),"",L27+14)) | Q27: =IF(AND($A27<>"",ISNUMBER(M27)),COUNTIF($M$4:$M$200,">"&M27)+COUNTIF($M$4:M27,M27),"")
B28: =IFERROR(INDEX('Position Database'!B:B,MATCH($A28,'Position Database'!$A:$A,0)),"") | C28: =IFERROR(INDEX('Position Database'!C:C,MATCH($A28,'Position Database'!$A:$A,0)),"") | D28: =IFERROR(INDEX('Position Database'!D:D,MATCH($A28,'Position Database'!$A:$A,0)),"") | L28: =IF(COUNT(E28,I28,J28,K28)=0,"",MAX(E28,I28,J28,K28)) | M28: =IF(OR($A28="",NOT(ISNUMBER(L28))),"",IF(OR(O28="Positive Reply",O28="Accepted",O28="Rejected"),"",TODAY()-L28)) | N28: =IF(OR($A28="",NOT(ISNUMBER(L28))),"",IF(OR(O28="Positive Reply",O28="Accepted",O28="Rejected"),"",L28+14)) | Q28: =IF(AND($A28<>"",ISNUMBER(M28)),COUNTIF($M$4:$M$200,">"&M28)+COUNTIF($M$4:M28,M28),"")
B29: =IFERROR(INDEX('Position Database'!B:B,MATCH($A29,'Position Database'!$A:$A,0)),"") | C29: =IFERROR(INDEX('Position Database'!C:C,MATCH($A29,'Position Database'!$A:$A,0)),"") | D29: =IFERROR(INDEX('Position Database'!D:D,MATCH($A29,'Position Database'!$A:$A,0)),"") | L29: =IF(COUNT(E29,I29,J29,K29)=0,"",MAX(E29,I29,J29,K29)) | M29: =IF(OR($A29="",NOT(ISNUMBER(L29))),"",IF(OR(O29="Positive Reply",O29="Accepted",O29="Rejected"),"",TODAY()-L29)) | N29: =IF(OR($A29="",NOT(ISNUMBER(L29))),"",IF(OR(O29="Positive Reply",O29="Accepted",O29="Rejected"),"",L29+14)) | Q29: =IF(AND($A29<>"",ISNUMBER(M29)),COUNTIF($M$4:$M$200,">"&M29)+COUNTIF($M$4:M29,M29),"")
B30: =IFERROR(INDEX('Position Database'!B:B,MATCH($A30,'Position Database'!$A:$A,0)),"") | C30: =IFERROR(INDEX('Position Database'!C:C,MATCH($A30,'Position Database'!$A:$A,0)),"") | D30: =IFERROR(INDEX('Position Database'!D:D,MATCH($A30,'Position Database'!$A:$A,0)),"") | L30: =IF(COUNT(E30,I30,J30,K30)=0,"",MAX(E30,I30,J30,K30)) | M30: =IF(OR($A30="",NOT(ISNUMBER(L30))),"",IF(OR(O30="Positive Reply",O30="Accepted",O30="Rejected"),"",TODAY()-L30)) | N30: =IF(OR($A30="",NOT(ISNUMBER(L30))),"",IF(OR(O30="Positive Reply",O30="Accepted",O30="Rejected"),"",L30+14)) | Q30: =IF(AND($A30<>"",ISNUMBER(M30)),COUNTIF($M$4:$M$200,">"&M30)+COUNTIF($M$4:M30,M30),"")
B31: =IFERROR(INDEX('Position Database'!B:B,MATCH($A31,'Position Database'!$A:$A,0)),"") | C31: =IFERROR(INDEX('Position Database'!C:C,MATCH($A31,'Position Database'!$A:$A,0)),"") | D31: =IFERROR(INDEX('Position Database'!D:D,MATCH($A31,'Position Database'!$A:$A,0)),"") | L31: =IF(COUNT(E31,I31,J31,K31)=0,"",MAX(E31,I31,J31,K31)) | M31: =IF(OR($A31="",NOT(ISNUMBER(L31))),"",IF(OR(O31="Positive Reply",O31="Accepted",O31="Rejected"),"",TODAY()-L31)) | N31: =IF(OR($A31="",NOT(ISNUMBER(L31))),"",IF(OR(O31="Positive Reply",O31="Accepted",O31="Rejected"),"",L31+14)) | Q31: =IF(AND($A31<>"",ISNUMBER(M31)),COUNTIF($M$4:$M$200,">"&M31)+COUNTIF($M$4:M31,M31),"")
B32: =IFERROR(INDEX('Position Database'!B:B,MATCH($A32,'Position Database'!$A:$A,0)),"") | C32: =IFERROR(INDEX('Position Database'!C:C,MATCH($A32,'Position Database'!$A:$A,0)),"") | D32: =IFERROR(INDEX('Position Database'!D:D,MATCH($A32,'Position Database'!$A:$A,0)),"") | L32: =IF(COUNT(E32,I32,J32,K32)=0,"",MAX(E32,I32,J32,K32)) | M32: =IF(OR($A32="",NOT(ISNUMBER(L32))),"",IF(OR(O32="Positive Reply",O32="Accepted",O32="Rejected"),"",TODAY()-L32)) | N32: =IF(OR($A32="",NOT(ISNUMBER(L32))),"",IF(OR(O32="Positive Reply",O32="Accepted",O32="Rejected"),"",L32+14)) | Q32: =IF(AND($A32<>"",ISNUMBER(M32)),COUNTIF($M$4:$M$200,">"&M32)+COUNTIF($M$4:M32,M32),"")
B33: =IFERROR(INDEX('Position Database'!B:B,MATCH($A33,'Position Database'!$A:$A,0)),"") | C33: =IFERROR(INDEX('Position Database'!C:C,MATCH($A33,'Position Database'!$A:$A,0)),"") | D33: =IFERROR(INDEX('Position Database'!D:D,MATCH($A33,'Position Database'!$A:$A,0)),"") | L33: =IF(COUNT(E33,I33,J33,K33)=0,"",MAX(E33,I33,J33,K33)) | M33: =IF(OR($A33="",NOT(ISNUMBER(L33))),"",IF(OR(O33="Positive Reply",O33="Accepted",O33="Rejected"),"",TODAY()-L33)) | N33: =IF(OR($A33="",NOT(ISNUMBER(L33))),"",IF(OR(O33="Positive Reply",O33="Accepted",O33="Rejected"),"",L33+14)) | Q33: =IF(AND($A33<>"",ISNUMBER(M33)),COUNTIF($M$4:$M$200,">"&M33)+COUNTIF($M$4:M33,M33),"")
B34: =IFERROR(INDEX('Position Database'!B:B,MATCH($A34,'Position Database'!$A:$A,0)),"") | C34: =IFERROR(INDEX('Position Database'!C:C,MATCH($A34,'Position Database'!$A:$A,0)),"") | D34: =IFERROR(INDEX('Position Database'!D:D,MATCH($A34,'Position Database'!$A:$A,0)),"") | L34: =IF(COUNT(E34,I34,J34,K34)=0,"",MAX(E34,I34,J34,K34)) | M34: =IF(OR($A34="",NOT(ISNUMBER(L34))),"",IF(OR(O34="Positive Reply",O34="Accepted",O34="Rejected"),"",TODAY()-L34)) | N34: =IF(OR($A34="",NOT(ISNUMBER(L34))),"",IF(OR(O34="Positive Reply",O34="Accepted",O34="Rejected"),"",L34+14)) | Q34: =IF(AND($A34<>"",ISNUMBER(M34)),COUNTIF($M$4:$M$200,">"&M34)+COUNTIF($M$4:M34,M34),"")
B35: =IFERROR(INDEX('Position Database'!B:B,MATCH($A35,'Position Database'!$A:$A,0)),"") | C35: =IFERROR(INDEX('Position Database'!C:C,MATCH($A35,'Position Database'!$A:$A,0)),"") | D35: =IFERROR(INDEX('Position Database'!D:D,MATCH($A35,'Position Database'!$A:$A,0)),"") | L35: =IF(COUNT(E35,I35,J35,K35)=0,"",MAX(E35,I35,J35,K35)) | M35: =IF(OR($A35="",NOT(ISNUMBER(L35))),"",IF(OR(O35="Positive Reply",O35="Accepted",O35="Rejected"),"",TODAY()-L35)) | N35: =IF(OR($A35="",NOT(ISNUMBER(L35))),"",IF(OR(O35="Positive Reply",O35="Accepted",O35="Rejected"),"",L35+14)) | Q35: =IF(AND($A35<>"",ISNUMBER(M35)),COUNTIF($M$4:$M$200,">"&M35)+COUNTIF($M$4:M35,M35),"")
... B200: =IFERROR(INDEX('Position Database'!B:B,MATCH($A200,'Position Database'!$A:$A,0)),"") | C200: =IFERROR(INDEX('Position Database'!C:C,MATCH($A200,'Position Database'!$A:$A,0)),"") | D200: =IFERROR(INDEX('Position Database'!D:D,MATCH($A200,'Position Database'!$A:$A,0)),"") | L200: =IF(COUNT(E200,I200,J200,K200)=0,"",MAX(E200,I200,J200,K200)) | M200: =IF(OR($A200="",NOT(ISNUMBER(L200))),"",IF(OR(O200="Positive Reply",O200="Accepted",O200="Rejected"),"",TODAY()-L200)) | N200: =IF(OR($A200="",NOT(ISNUMBER(L200))),"",IF(OR(O200="Positive Reply",O200="Accepted",O200="Rejected"),"",L200+14)) | Q200: =IF(AND($A200<>"",ISNUMBER(M200)),COUNTIF($M$4:$M$200,">"&M200)+COUNTIF($M$4:M200,M200),"")

Sheet Response Management
A1: Response Management
A2: Log every reply you receive. Pick the position ID from the drop-down. Update the Status in the Communication Tracker as well so the follow-up clock stops. | H2: ◀ Back to Dashboard
A3: ID | B3: Position Title | C3: University | D3: Reply Date | E3: Reply Status | F3: Reply Summary | G3: Meeting Date | H3: Outcome | I3: Next Action
A4: 1 | B4: =IFERROR(INDEX('Position Database'!B:B,MATCH($A4,'Position Database'!$A:$A,0)),"") -> Post Doc: Learning Interactions in Collective Cell Migration | C4: =IFERROR(INDEX('Position Database'!C:C,MATCH($A4,'Position Database'!$A:$A,0)),"") -> Vrije Universiteit Amsterdam | D4: 46273 | E4: Positive Reply | F4: Expressed interest; asked for the full proposal and a funding plan | G4: 46287 | H4: Proposal Requested | I4: Send the two-page research proposal
A5: 4 | B5: =IFERROR(INDEX('Position Database'!B:B,MATCH($A5,'Position Database'!$A:$A,0)),"") -> PhD Candidate: Multi-Methods Project on Negation Across Languages | C5: =IFERROR(INDEX('Position Database'!C:C,MATCH($A5,'Position Database'!$A:$A,0)),"") -> University of Amsterdam | D5: 46267 | E5: Neutral Reply | F5: No budget at the moment but open to a conversation | H5: Info Received | I5: Check NWO grant options
A6: 5 | B6: =IFERROR(INDEX('Position Database'!B:B,MATCH($A6,'Position Database'!$A:$A,0)),"") -> PhD Position: Beyond the Odds - Pathways to Gambling-Related Harm | C6: =IFERROR(INDEX('Position Database'!C:C,MATCH($A6,'Position Database'!$A:$A,0)),"") -> Radboud University | D6: 46279 | E6: Rejected | F6: Position has been filled | H6: Closed | I6: Remove from follow-up list
A7: 6 | B7: =IFERROR(INDEX('Position Database'!B:B,MATCH($A7,'Position Database'!$A:$A,0)),"") -> PhD Position in Time-Reflection of Subwavelength THz Waves | C7: =IFERROR(INDEX('Position Database'!C:C,MATCH($A7,'Position Database'!$A:$A,0)),"") -> ETH Zurich | D7: 46285 | E7: Interview Invitation | F7: Invited to a 30-minute online interview with the group leader | G7: 46298 | H7: Interview Scheduled | I7: Prepare a 5-minute research pitch
A8: 9 | B8: =IFERROR(INDEX('Position Database'!B:B,MATCH($A8,'Position Database'!$A:$A,0)),"") -> Two Postdoctoral Positions in Mitochondrial Cell Biology | C8: =IFERROR(INDEX('Position Database'!C:C,MATCH($A8,'Position Database'!$A:$A,0)),"") -> Institut Imagine | D8: 46281 | E8: Positive Reply | F8: Asked for a writing sample and two referees | H8: Proposal Requested | I8: Send writing sample and referee list
A9: 10 | B9: =IFERROR(INDEX('Position Database'!B:B,MATCH($A9,'Position Database'!$A:$A,0)),"") -> Doctoral Student in Environmental Law Specialising in Nuclear Power | C9: =IFERROR(INDEX('Position Database'!C:C,MATCH($A9,'Position Database'!$A:$A,0)),"") -> Uppsala University | D9: 46264 | E9: Accepted | F9: Formal acceptance; start date January 2027 | G9: 46270 | H9: Accepted | I9: Start the residence-permit process
A10: 13 | B10: =IFERROR(INDEX('Position Database'!B:B,MATCH($A10,'Position Database'!$A:$A,0)),"") -> Postdoc: Multiphysics Modelling of Laser-Regolith Interaction (Moon) | C10: =IFERROR(INDEX('Position Database'!C:C,MATCH($A10,'Position Database'!$A:$A,0)),"") -> Technical University of Denmark | D10: 46284 | E10: Neutral Reply | F10: Position still open but priority is given to internal candidates | H10: Info Received | I10: Follow up again in November
A11: 16 | B11: =IFERROR(INDEX('Position Database'!B:B,MATCH($A11,'Position Database'!$A:$A,0)),"") -> Postdoc in Synthesis and Crystal Growth of Molecular Conductors | C11: =IFERROR(INDEX('Position Database'!C:C,MATCH($A11,'Position Database'!$A:$A,0)),"") -> Chalmers University of Technology | D11: 46286 | E11: Interview Invitation | F11: Invited to an introductory meeting with the research team | G11: 46303 | H11: Interview Scheduled | I11: Review the group's recent papers
A12: 17 | B12: =IFERROR(INDEX('Position Database'!B:B,MATCH($A12,'Position Database'!$A:$A,0)),"") -> PhD Candidate in Children's Media in English (CLEAR Group) | C12: =IFERROR(INDEX('Position Database'!C:C,MATCH($A12,'Position Database'!$A:$A,0)),"") -> NTNU | D12: 46270 | E12: Rejected | F12: Research area does not match | H12: Closed | I12: Remove from follow-up list
A13: 20 | B13: =IFERROR(INDEX('Position Database'!B:B,MATCH($A13,'Position Database'!$A:$A,0)),"") -> Postdoctoral Fellows in Proteomics: Neurodevelopment and Cancer | C13: =IFERROR(INDEX('Position Database'!C:C,MATCH($A13,'Position Database'!$A:$A,0)),"") -> University of Helsinki | D13: 46280 | E13: Neutral Reply | F13: Referred to another colleague in the same faculty | H13: Info Received | I13: Contact the referred professor
B14: =IFERROR(INDEX('Position Database'!B:B,MATCH($A14,'Position Database'!$A:$A,0)),"") | C14: =IFERROR(INDEX('Position Database'!C:C,MATCH($A14,'Position Database'!$A:$A,0)),"")
B15: =IFERROR(INDEX('Position Database'!B:B,MATCH($A15,'Position Database'!$A:$A,0)),"") | C15: =IFERROR(INDEX('Position Database'!C:C,MATCH($A15,'Position Database'!$A:$A,0)),"")
B16: =IFERROR(INDEX('Position Database'!B:B,MATCH($A16,'Position Database'!$A:$A,0)),"") | C16: =IFERROR(INDEX('Position Database'!C:C,MATCH($A16,'Position Database'!$A:$A,0)),"")
B17: =IFERROR(INDEX('Position Database'!B:B,MATCH($A17,'Position Database'!$A:$A,0)),"") | C17: =IFERROR(INDEX('Position Database'!C:C,MATCH($A17,'Position Database'!$A:$A,0)),"")
B18: =IFERROR(INDEX('Position Database'!B:B,MATCH($A18,'Position Database'!$A:$A,0)),"") | C18: =IFERROR(INDEX('Position Database'!C:C,MATCH($A18,'Position Database'!$A:$A,0)),"")
B19: =IFERROR(INDEX('Position Database'!B:B,MATCH($A19,'Position Database'!$A:$A,0)),"") | C19: =IFERROR(INDEX('Position Database'!C:C,MATCH($A19,'Position Database'!$A:$A,0)),"")
B20: =IFERROR(INDEX('Position Database'!B:B,MATCH($A20,'Position Database'!$A:$A,0)),"") | C20: =IFERROR(INDEX('Position Database'!C:C,MATCH($A20,'Position Database'!$A:$A,0)),"")
B21: =IFERROR(INDEX('Position Database'!B:B,MATCH($A21,'Position Database'!$A:$A,0)),"") | C21: =IFERROR(INDEX('Position Database'!C:C,MATCH($A21,'Position Database'!$A:$A,0)),"")
B22: =IFERROR(INDEX('Position Database'!B:B,MATCH($A22,'Position Database'!$A:$A,0)),"") | C22: =IFERROR(INDEX('Position Database'!C:C,MATCH($A22,'Position Database'!$A:$A,0)),"")
B23: =IFERROR(INDEX('Position Database'!B:B,MATCH($A23,'Position Database'!$A:$A,0)),"") | C23: =IFERROR(INDEX('Position Database'!C:C,MATCH($A23,'Position Database'!$A:$A,0)),"")
B24: =IFERROR(INDEX('Position Database'!B:B,MATCH($A24,'Position Database'!$A:$A,0)),"") | C24: =IFERROR(INDEX('Position Database'!C:C,MATCH($A24,'Position Database'!$A:$A,0)),"")
B25: =IFERROR(INDEX('Position Database'!B:B,MATCH($A25,'Position Database'!$A:$A,0)),"") | C25: =IFERROR(INDEX('Position Database'!C:C,MATCH($A25,'Position Database'!$A:$A,0)),"")
... B119: =IFERROR(INDEX('Position Database'!B:B,MATCH($A119,'Position Database'!$A:$A,0)),"") | C119: =IFERROR(INDEX('Position Database'!C:C,MATCH($A119,'Position Database'!$A:$A,0)),"")

Sheet Follow-up Alerts
A1: Follow-up Alerts
A2: Red = more than 14 days, send a follow-up today | Amber = 7 to 14 days, prepare it | Green = under 7 days, keep watching | G2: ◀ Back to Dashboard
A3: # | B3: Position Title | C3: University | D3: Days Since | E3: Last Contact | F3: Next Follow-up | G3: Status | H3: Recommended Action
A4: =IF('Communication Tracker'!B4="","",1) -> 1 | B4: =IF('Communication Tracker'!B4="","",'Communication Tracker'!B4) -> Post Doc: Learning Interactions in Collective Cell Migration | C4: =IF('Communication Tracker'!C4="","",'Communication Tracker'!C4) -> Vrije Universiteit Amsterdam | D4: =IFERROR(IF(ISNUMBER('Communication Tracker'!M4),'Communication Tracker'!M4,""),"") | E4: =IFERROR('Communication Tracker'!L4,"") -> 46267 | F4: =IFERROR(IF(ISNUMBER('Communication Tracker'!N4),'Communication Tracker'!N4,""),"") | G4: =IF('Communication Tracker'!O4="","",'Communication Tracker'!O4) -> Positive Reply | H4: =IF('Communication Tracker'!B4="","",IF(OR('Communication Tracker'!O4="Positive Reply",'Communication Tracker'!O4="Accepted",'Communication Tracker'!O4="Rejected"),"Case closed - no action needed",IF(ISNUMBER('Communication Tracker'!M4),IF('Communication Tracker'!M4>14,"URGENT - send a follow-up today",IF('Communication Tracker'!M4>=7,"Prepare follow-up - send within "&(14-'Communication Tracker'!M4)&" days","Monitoring - next follow-up in "&(14-'Communication Tracker'!M4)&" days")),""))) -> Case closed - no action needed
